Workbook

Sheet Резултати мјерења
A1: RBM | B1: Udc [V] | E1: Idc [mA] | H1: ϑD [°C] | K1: ϑG [°C] | N1: ϑJ [°C] | Q1: Uk [V] | T1: Ik [A] | W1: Pk [W]
B2: α | C2: k | E2: α | F2: k | H2: α | I2: k | K2: α | L2: k | N2: α | O2: k | Q2: α | R2: k | T2: α | U2: k | W2: α | X2: k
A3: 1 | B3: 11.6 | C3: 1 | D3: =B3*C3 -> 11.6 | E3: 210 | F3: 1 | G3: =E3*F3 -> 210 | H3: 20.6 | I3: 1 | J3: =H3*I3 -> 20.6 | K3: 20.6 | L3: 1 | M3: =K3*L3 -> 20.6 | N3: 20.6 | O3: 1 | P3: =N3*O3 -> 20.6 | Q3: 55 | R3: 1 | S3: =Q3*R3 -> 55 | T3: 0.4 | U3: 1 | V3: =T3*U3 -> 0.4 | W3: 86 | X3: 0.25 | Y3: =W3*X3 -> 21.5
A4: 2 | B4: 11.5 | C4: 1 | D4: =B4*C4 -> 11.5 | E4: 190 | F4: 1 | G4: =E4*F4 -> 190 | H4: 23.4 | I4: 1 | J4: =H4*I4 -> 23.4 | K4: 36.6 | L4: 1 | M4: =K4*L4 -> 36.6 | N4: 24.5 | O4: 1 | P4: =N4*O4 -> 24.5
A5: 3 | B5: 11.7 | C5: 1 | D5: =B5*C5 -> 11.7 | E5: 185 | F5: 1 | G5: =E5*F5 -> 185 | H5: 27 | I5: 1 | J5: =H5*I5 -> 27 | K5: 43.7 | L5: 1 | M5: =K5*L5 -> 43.7 | N5: 29.2 | O5: 1 | P5: =N5*O5 -> 29.2
A6: 4 | B6: 11.85 | C6: 1 | D6: =B6*C6 -> 11.85 | E6: 180 | F6: 1 | G6: =E6*F6 -> 180 | H6: 27.5 | I6: 1 | J6: =H6*I6 -> 27.5 | K6: 49 | L6: 1 | M6: =K6*L6 -> 49 | N6: 33.5 | O6: 1 | P6: =N6*O6 -> 33.5
A7: 5 | B7: 11.9 | C7: 1 | D7: =B7*C7 -> 11.9 | E7: 180 | F7: 1 | G7: =E7*F7 -> 180 | H7: 28 | I7: 1 | J7: =H7*I7 -> 28 | K7: 52.3 | L7: 1 | M7: =K7*L7 -> 52.3 | N7: 35.7 | O7: 1 | P7: =N7*O7 -> 35.7
A8: 6 | B8: 11.95 | C8: 1 | D8: =B8*C8 -> 11.95 | E8: 185 | F8: 1 | G8: =E8*F8 -> 185 | H8: 30.4 | I8: 1 | J8: =H8*I8 -> 30.4 | K8: 54.5 | L8: 1 | M8: =K8*L8 -> 54.5 | N8: 34.1 | O8: 1 | P8: =N8*O8 -> 34.1
A9: 7 | B9: 11.95 | C9: 1 | D9: =B9*C9 -> 11.95 | E9: 185 | F9: 1 | G9: =E9*F9 -> 185 | H9: 37 | I9: 1 | J9: =H9*I9 -> 37 | K9: 56.4 | L9: 1 | M9: =K9*L9 -> 56.4 | N9: 37.5 | O9: 1 | P9: =N9*O9 -> 37.5
A10: 8 | B10: 11.85 | C10: 1 | D10: =B10*C10 -> 11.85 | E10: 185 | F10: 1 | G10: =E10*F10 -> 185 | H10: 37.9 | I10: 1 | J10: =H10*I10 -> 37.9 | K10: 57.7 | L10: 1 | M10: =K10*L10 -> 57.7 | N10: 38.5 | O10: 1 | P10: =N10*O10 -> 38.5
A11: 9 | B11: 11.8 | C11: 1 | D11: =B11*C11 -> 11.8 | E11: 175 | F11: 1 | G11: =E11*F11 -> 175 | H11: 37.2 | I11: 1 | J11: =H11*I11 -> 37.2 | K11: 59 | L11: 1 | M11: =K11*L11 -> 59 | N11: 37.8 | O11: 1 | P11: =N11*O11 -> 37.8
A12: 10 | B12: 11.8 | C12: 1 | D12: =B12*C12 -> 11.8 | E12: 175 | F12: 1 | G12: =E12*F12 -> 175 | H12: 39.9 | I12: 1 | J12: =H12*I12 -> 39.9 | K12: 61.3 | L12: 1 | M12: =K12*L12 -> 61.3 | N12: 43.4 | O12: 1 | P12: =N12*O12 -> 43.4
A16: ϑa | B16: 20.6 | C16: °C
A17: R'dc | B17: 56.3 | C17: Ω
A18: R''dc | B18: 3.3 | C18: Ω
A19: ϑ | B19: 75 | C19: °C
A20: R'dc | B20: =$B$17*(235+$B$19)/(235+$B$16) -> 68.282473 | C20: Ω
A21: R''dc | B21: =$B$18*(235+$B$19)/(235+$B$16) -> 4.0023474 | C21: Ω
A22: ukn% | B22: =$S$3/660*(0.45/$V$3) -> 0.09375
A23: urn% | B23: =$Y$3/297*(0.45^2/$V$3^2) -> 0.091619318
A24: uxn% | B24: =($B$22^2-$B$23^2)^(1/2) -> 0.019873677

Sheet Δu%=f(cosϕ) у хладном стању
A1: U1n | B1: 660 | C1: V | E1: cosϕ | F1: sinϕ | G1: an% | H1: bn% | I1: Δu%
A2: U2n | B2: 110 | C2: V | E2: 0 | F2: -1 | G2: =$B$12*E2+$B$13*F2 -> -0.019873677 | H2: =$B$13*E2-$B$12*F2 -> 0.091619318 | I2: =$B$14*G2+($B$14^2*H2^2)/200 -> -0.019831706
A3: Sn | B3: 297 | C3: VA | E3: 0.01 | F3: -0.99995 | G3: =$B$12*E3+$B$13*F3 -> -0.01895649 | H3: =$B$13*E3-$B$12*F3 -> 0.091813474 | I3: =$B$14*G3+($B$14^2*H3^2)/200 -> -0.018914341
A4: I1n | B4: 0.45 | C4: A | E4: 0.02 | F4: -0.99979998 | G4: =$B$12*E4+$B$13*F4 -> -0.018037315 | H4: =$B$13*E4-$B$12*F4 -> 0.091998466 | I4: =$B$14*G4+($B$14^2*H4^2)/200 -> -0.017994997
A5: I2n | B5: 2.7 | C5: A | E5: 0.03 | F5: -0.9995499 | G5: =$B$12*E5+$B$13*F5 -> -0.017116152 | H5: =$B$13*E5-$B$12*F5 -> 0.092174291 | I5: =$B$14*G5+($B$14^2*H5^2)/200 -> -0.017073672
A6: Uk | B6: ='Резултати мјерења'!$Q$3*'Резултати мјерења'!$R$3 -> 55 | C6: V | E6: 0.04 | F6: -0.99919968 | G6: =$B$12*E6+$B$13*F6 -> -0.016192999 | H6: =$B$13*E6-$B$12*F6 -> 0.09234094 | I6: =$B$14*G6+($B$14^2*H6^2)/200 -> -0.016150365
A7: Pk | B7: ='Резултати мјерења'!$W$3*'Резултати мјерења'!$X$3 -> 21.5 | C7: W | E7: 0.05 | F7: -0.99874922 | G7: =$B$12*E7+$B$13*F7 -> -0.015267853 | H7: =$B$13*E7-$B$12*F7 -> 0.092498406 | I7: =$B$14*G7+($B$14^2*H7^2)/200 -> -0.015225074
A8: Ik | B8: ='Резултати мјерења'!$T$3*'Резултати мјерења'!$U$3 -> 0.4 | C8: A | E8: 0.06 | F8: -0.99819838 | G8: =$B$12*E8+$B$13*F8 -> -0.014340713 | H8: =$B$13*E8-$B$12*F8 -> 0.092646675 | I8: =$B$14*G8+($B$14^2*H8^2)/200 -> -0.014297796
A9: Ukn | B9: =B6*(B4/B8) -> 61.875 | C9: V | E9: 0.07 | F9: -0.99754699 | G9: =$B$12*E9+$B$13*F9 -> -0.013411574 | H9: =$B$13*E9-$B$12*F9 -> 0.092785733 | I9: =$B$14*G9+($B$14^2*H9^2)/200 -> -0.013368528
A10: Pkn | B10: =B7*(B4^2/B8^2) -> 27.210937 | C10: W | E10: 0.08 | F10: -0.99679486 | G10: =$B$12*E10+$B$13*F10 -> -0.012480434 | H10: =$B$13*E10-$B$12*F10 -> 0.09291556 | I10: =$B$14*G10+($B$14^2*H10^2)/200 -> -0.012437267
A11: ukn% | B11: ='Резултати мјерења'!B22 -> 0.09375 | E11: 0.09 | F11: -0.99594177 | G11: =$B$12*E11+$B$13*F11 -> -0.011547286 | H11: =$B$13*E11-$B$12*F11 -> 0.093036136 | I11: =$B$14*G11+($B$14^2*H11^2)/200 -> -0.011504008
A12: urn% | B12: ='Резултати мјерења'!B23 -> 0.091619318 | E12: 0.1 | F12: -0.99498744 | G12: =$B$12*E12+$B$13*F12 -> -0.010612127 | H12: =$B$13*E12-$B$12*F12 -> 0.093147438 | I12: =$B$14*G12+($B$14^2*H12^2)/200 -> -0.010568745
A13: uxn% | B13: ='Резултати мјерења'!B24 -> 0.019873677 | E13: 0.11 | F13: -0.99393159 | G13: =$B$12*E13+$B$13*F13 -> -0.0096749503 | H13: =$B$13*E13-$B$12*F13 -> 0.093249439 | I13: =$B$14*G13+($B$14^2*H13^2)/200 -> -0.009631473
A14: β=I2/I2n | B14: 1 | E14: 0.12 | F14: -0.99277389 | G14: =$B$12*E14+$B$13*F14 -> -0.0087357494 | H14: =$B$13*E14-$B$12*F14 -> 0.093342108 | I14: =$B$14*G14+($B$14^2*H14^2)/200 -> -0.0086921857
A15: cos(ϕ)kn | B15: =B10/(B9*B4) -> 0.97727273 | E15: 0.13 | F15: -0.99151399 | G15: =$B$12*E15+$B$13*F15 -> -0.0077945175 | H15: =$B$13*E15-$B$12*F15 -> 0.093425414 | I15: =$B$14*G15+($B$14^2*H15^2)/200 -> -0.0077508759
A16: Zk | B16: =B9/B4 -> 137.5 | C16: Ω | E16: 0.14 | F16: -0.9901515 | G16: =$B$12*E16+$B$13*F16 -> -0.0068512466 | H16: =$B$13*E16-$B$12*F16 -> 0.09349932 | I16: =$B$14*G16+($B$14^2*H16^2)/200 -> -0.006807536
A17: Rk | B17: =B16*B15 -> 134.375 | C17: Ω | E17: 0.15 | F17: -0.988686 | G17: =$B$12*E17+$B$13*F17 -> -0.0059059284 | H17: =$B$13*E17-$B$12*F17 -> 0.093563788 | I17: =$B$14*G17+($B$14^2*H17^2)/200 -> -0.0058621575
A18: Xk | B18: =$B$16*(1-$B$15^2)^(1/2) -> 29.14806 | C18: Ω | E18: 0.16 | F18: -0.98711701 | G18: =$B$12*E18+$B$13*F18 -> -0.0049585538 | H18: =$B$13*E18-$B$12*F18 -> 0.093618776 | I18: =$B$14*G18+($B$14^2*H18^2)/200 -> -0.0049147314
E19: 0.17 | F19: -0.98544406 | G19: =$B$12*E19+$B$13*F19 -> -0.0040091129 | H19: =$B$13*E19-$B$12*F19 -> 0.093664238 | I19: =$B$14*G19+($B$14^2*H19^2)/200 -> -0.0039652479
E20: 0.18 | F20: -0.98366661 | G20: =$B$12*E20+$B$13*F20 -> -0.0030575952 | H20: =$B$13*E20-$B$12*F20 -> 0.093700126 | I20: =$B$14*G20+($B$14^2*H20^2)/200 -> -0.0030136966 | AH20: cos(ϕ) | AI20: sin(ϕ) | AJ20: Δu%
E21: 0.19 | F21: -0.98178409 | G21: =$B$12*E21+$B$13*F21 -> -0.0021039894 | H21: =$B$13*E21-$B$12*F21 -> 0.093726388 | I21: =$B$14*G21+($B$14^2*H21^2)/200 -> -0.0020600662 | AH21: 0 | AI21: =SQRT(1-POWER(AH21, 2)) -> 1 | AJ21: 2.4067
E22: 0.2 | F22: -0.9797959 | G22: =$B$12*E22+$B$13*F22 -> -0.0011482835 | H22: =$B$13*E22-$B$12*F22 -> 0.093742967 | I22: =$B$14*G22+($B$14^2*H22^2)/200 -> -0.0011043448 | AH22: 0.2 | AI22: =SQRT(1-POWER(AH22, 2)) -> 0.9797959 | AJ22: 4.1473
E23: 0.21 | F23: -0.97770139 | G23: =$B$12*E23+$B$13*F23 -> -0.00019046469 | H23: =$B$13*E23-$B$12*F23 -> 0.093749807 | I23: =$B$14*G23+($B$14^2*H23^2)/200 -> -0.00014651956 | AH23: 0.4 | AI23: =SQRT(1-POWER(AH23, 2)) -> 0.91651514 | AJ23: 5.7749
E24: 0.22 | F24: -0.97549987 | G24: =$B$12*E24+$B$13*F24 -> 0.00076948067 | H24: =$B$13*E24-$B$12*F24 -> 0.093746842 | I24: =$B$14*G24+($B$14^2*H24^2)/200 -> 0.00081342302 | AH24: 0.6 | AI24: =SQRT(1-POWER(AH24, 2)) -> 0.8 | AJ24: 7.2751
E25: 0.23 | F25: -0.97319063 | G25: =$B$12*E25+$B$13*F25 -> 0.001731567 | H25: =$B$13*E25-$B$12*F25 -> 0.093734008 | I25: =$B$14*G25+($B$14^2*H25^2)/200 -> 0.0017754973 | AH25: 0.8 | AI25: =SQRT(1-POWER(AH25, 2)) -> 0.6 | AJ25: 8.5981
E26: 0.24 | F26: -0.97077289 | G26: =$B$12*E26+$B$13*F26 -> 0.0026958096 | H26: =$B$13*E26-$B$12*F26 -> 0.093711233 | I26: =$B$14*G26+($B$14^2*H26^2)/200 -> 0.0027397186 | AH26: 1 | AI26: =SQRT(1-POWER(AH26, 2)) -> 0 | AJ26: 9.1817
E27: 0.25 | F27: -0.96824584 | G27: =$B$12*E27+$B$13*F27 -> 0.0036622246 | H27: =$B$13*E27-$B$12*F27 -> 0.093678443 | I27: =$B$14*G27+($B$14^2*H27^2)/200 -> 0.0037061028 | AH27: 0.8 | AI27: =-SQRT(1-POWER(AH27, 2)) -> -0.6 | AJ27: 6.3885
E28: 0.26 | F28: -0.96560862 | G28: =$B$12*E28+$B$13*F28 -> 0.004630829 | H28: =$B$13*E28-$B$12*F28 -> 0.093635559 | I28: =$B$14*G28+($B$14^2*H28^2)/200 -> 0.0046746671 | AH28: 0.6 | AI28: =-SQRT(1-POWER(AH28, 2)) -> -0.8 | AJ28: 4.2707
E29: 0.27 | F29: -0.96286032 | G29: =$B$12*E29+$B$13*F29 -> 0.0056016409 | H29: =$B$13*E29-$B$12*F29 -> 0.093582499 | I29: =$B$14*G29+($B$14^2*H29^2)/200 -> 0.0056454293 | AH29: 0.4 | AI29: =-SQRT(1-POWER(AH29, 2)) -> -0.91651514 | AJ29: 2.2661
E30: 0.28 | F30: -0.96 | G30: =$B$12*E30+$B$13*F30 -> 0.0065746792 | H30: =$B$13*E30-$B$12*F30 -> 0.093519175 | I30: =$B$14*G30+($B$14^2*H30^2)/200 -> 0.0066184084 | AH30: 0.2 | AI30: =-SQRT(1-POWER(AH30, 2)) -> -0.9797959 | AJ30: 0.3249
E31: 0.29 | F31: -0.95702665 | G31: =$B$12*E31+$B$13*F31 -> 0.0075499639 | H31: =$B$13*E31-$B$12*F31 -> 0.093445495 | I31: =$B$14*G31+($B$14^2*H31^2)/200 -> 0.0075936242 | AH31: 0 | AI31: =-SQRT(1-POWER(AH31, 2)) -> -1 | AJ31: -1.5673
E32: 0.3 | F32: -0.9539392 | G32: =$B$12*E32+$B$13*F32 -> 0.0085275159 | H32: =$B$13*E32-$B$12*F32 -> 0.093361362 | I32: =$B$14*G32+($B$14^2*H32^2)/200 -> 0.0085710976
E33: 0.31 | F33: -0.95073656 | G33: =$B$12*E33+$B$13*F33 -> 0.0095073574 | H33: =$B$13*E33-$B$12*F33 -> 0.093266675 | I33: =$B$14*G33+($B$14^2*H33^2)/200 -> 0.0095508508
E34: 0.32 | F34: -0.94741754 | G34: =$B$12*E34+$B$13*F34 -> 0.010489512 | H34: =$B$13*E34-$B$12*F34 -> 0.093161326 | I34: =$B$14*G34+($B$14^2*H34^2)/200 -> 0.010532907
E35: 0.33 | F35: -0.94398093 | G35: =$B$12*E35+$B$13*F35 -> 0.011474003 | H35: =$B$13*E35-$B$12*F35 -> 0.093045203 | I35: =$B$14*G35+($B$14^2*H35^2)/200 -> 0.01151729
E36: 0.34 | F36: -0.94042544 | G36: =$B$12*E36+$B$13*F36 -> 0.012460857 | H36: =$B$13*E36-$B$12*F36 -> 0.092918187 | I36: =$B$14*G36+($B$14^2*H36^2)/200 -> 0.012504026
E37: 0.35 | F37: -0.9367497 | G37: =$B$12*E37+$B$13*F37 -> 0.0134501 | H37: =$B$13*E37-$B$12*F37 -> 0.092780156 | I37: =$B$14*G37+($B$14^2*H37^2)/200 -> 0.013493141
E38: 0.36 | F38: -0.9329523 | G38: =$B$12*E38+$B$13*F38 -> 0.014441762 | H38: =$B$13*E38-$B$12*F38 -> 0.092630978 | I38: =$B$14*G38+($B$14^2*H38^2)/200 -> 0.014484664
E39: 0.37 | F39: -0.92903175 | G39: =$B$12*E39+$B$13*F39 -> 0.015435871 | H39: =$B$13*E39-$B$12*F39 -> 0.092470516 | I39: =$B$14*G39+($B$14^2*H39^2)/200 -> 0.015478625
E40: 0.38 | F40: -0.92498649 | G40: =$B$12*E40+$B$13*F40 -> 0.016432458 | H40: =$B$13*E40-$B$12*F40 -> 0.092298628 | I40: =$B$14*G40+($B$14^2*H40^2)/200 -> 0.016475053
...

Sheet Δu%=f(cosϕ) у топлом стању

Sheet U2=f(cosϕ)
A1: ukn% | B1: ='Резултати мјерења'!B22 -> 0.09375 | E1: β=I2/I2n | F1: Δu2_1 | G1: Δu2_2 | H1: Δu2_3 | I1: U2_1 | J1: U2_2 | K1: U2_3
A2: urn% | B2: ='Резултати мјерења'!B23 -> 0.091619318 | E2: 0 | F2: =E2*$B$7+(E2^2*$B$8^2)/200 -> 0 | G2: =E2*$B$12+(E2^2*$B$13^2)/200 -> 0 | H2: =E2*$B$17+(E2^2*$B$18^2)/200 -> 0 | I2: =$B$20-F2*$B$20 -> 110 | J2: =$B$20-G2*$B$20 -> 110 | K2: =$B$20-H2*$B$20 -> 110
A3: uxn% | B3: ='Резултати мјерења'!B24 -> 0.019873677 | E3: 0.01 | F3: =E3*$B$7+(E3^2*$B$8^2)/200 -> 0.000613715 | G3: =E3*$B$12+(E3^2*$B$13^2)/200 -> 0.00091619338 | H3: =E3*$B$17+(E3^2*$B$18^2)/200 -> 0.00085219737 | I3: =$B$20-F3*$B$20 -> 109.93249 | J3: =$B$20-G3*$B$20 -> 109.89922 | K3: =$B$20-H3*$B$20 -> 109.90626
E4: 0.02 | F4: =E4*$B$7+(E4^2*$B$8^2)/200 -> 0.001227435 | G4: =E4*$B$12+(E4^2*$B$13^2)/200 -> 0.0018323872 | H4: =E4*$B$17+(E4^2*$B$18^2)/200 -> 0.0017043963 | I4: =$B$20-F4*$B$20 -> 109.86498 | J4: =$B$20-G4*$B$20 -> 109.79844 | K4: =$B$20-H4*$B$20 -> 109.81252
A5: cosφ1 | B5: 0.8 | C5: cap | E5: 0.03 | F5: =E5*$B$7+(E5^2*$B$8^2)/200 -> 0.0018411601 | G5: =E5*$B$12+(E5^2*$B$13^2)/200 -> 0.0027485813 | H5: =E5*$B$17+(E5^2*$B$18^2)/200 -> 0.0025565967 | I5: =$B$20-F5*$B$20 -> 109.79747 | J5: =$B$20-G5*$B$20 -> 109.69766 | K5: =$B$20-H5*$B$20 -> 109.71877
A6: sinφ1 | B6: =-((1-$B$5^2)^(1/2)) -> -0.6 | C6: cap | E6: 0.04 | F6: =E6*$B$7+(E6^2*$B$8^2)/200 -> 0.0024548901 | G6: =E6*$B$12+(E6^2*$B$13^2)/200 -> 0.0036647759 | H6: =E6*$B$17+(E6^2*$B$18^2)/200 -> 0.0034087986 | I6: =$B$20-F6*$B$20 -> 109.72996 | J6: =$B$20-G6*$B$20 -> 109.59687 | K6: =$B$20-H6*$B$20 -> 109.62503
A7: an%1 | B7: =$B$2*$B$5+$B$3*$B$6 -> 0.061371248 | E7: 0.05 | F7: =E7*$B$7+(E7^2*$B$8^2)/200 -> 0.0030686252 | G7: =E7*$B$12+(E7^2*$B$13^2)/200 -> 0.0045809708 | H7: =E7*$B$17+(E7^2*$B$18^2)/200 -> 0.0042610021 | I7: =$B$20-F7*$B$20 -> 109.66245 | J7: =$B$20-G7*$B$20 -> 109.49609 | K7: =$B$20-H7*$B$20 -> 109.53129
A8: bn%1 | B8: =$B$3*$B$5-$B$2*$B$6 -> 0.070870532 | E8: 0.06 | F8: =E8*$B$7+(E8^2*$B$8^2)/200 -> 0.0036823653 | G8: =E8*$B$12+(E8^2*$B$13^2)/200 -> 0.0054971662 | H8: =E8*$B$17+(E8^2*$B$18^2)/200 -> 0.0051132071 | I8: =$B$20-F8*$B$20 -> 109.59494 | J8: =$B$20-G8*$B$20 -> 109.39531 | K8: =$B$20-H8*$B$20 -> 109.43755
E9: 0.07 | F9: =E9*$B$7+(E9^2*$B$8^2)/200 -> 0.0042961104 | G9: =E9*$B$12+(E9^2*$B$13^2)/200 -> 0.0064133619 | H9: =E9*$B$17+(E9^2*$B$18^2)/200 -> 0.0059654137 | I9: =$B$20-F9*$B$20 -> 109.52743 | J9: =$B$20-G9*$B$20 -> 109.29453 | K9: =$B$20-H9*$B$20 -> 109.3438
A10: cosφ2 | B10: 1 | E10: 0.08 | F10: =E10*$B$7+(E10^2*$B$8^2)/200 -> 0.0049098606 | G10: =E10*$B$12+(E10^2*$B$13^2)/200 -> 0.0073295581 | H10: =E10*$B$17+(E10^2*$B$18^2)/200 -> 0.0068176217 | I10: =$B$20-F10*$B$20 -> 109.45992 | J10: =$B$20-G10*$B$20 -> 109.19375 | K10: =$B$20-H10*$B$20 -> 109.25006
A11: sinφ2 | B11: =-((1-$B$10^2)^(1/2)) -> 0 | E11: 0.09 | F11: =E11*$B$7+(E11^2*$B$8^2)/200 -> 0.0055236158 | G11: =E11*$B$12+(E11^2*$B$13^2)/200 -> 0.0082457546 | H11: =E11*$B$17+(E11^2*$B$18^2)/200 -> 0.0076698313 | I11: =$B$20-F11*$B$20 -> 109.3924 | J11: =$B$20-G11*$B$20 -> 109.09297 | K11: =$B$20-H11*$B$20 -> 109.15632
A12: an%2 | B12: =$B$2*$B$10+$B$3*$B$11 -> 0.091619318 | E12: 0.1 | F12: =E12*$B$7+(E12^2*$B$8^2)/200 -> 0.006137376 | G12: =E12*$B$12+(E12^2*$B$13^2)/200 -> 0.0091619516 | H12: =E12*$B$17+(E12^2*$B$18^2)/200 -> 0.0085220424 | I12: =$B$20-F12*$B$20 -> 109.32489 | J12: =$B$20-G12*$B$20 -> 108.99219 | K12: =$B$20-H12*$B$20 -> 109.06258
A13: bn%2 | B13: =$B$3*$B$10-$B$2*$B$11 -> 0.019873677 | E13: 0.11 | F13: =E13*$B$7+(E13^2*$B$8^2)/200 -> 0.0067511412 | G13: =E13*$B$12+(E13^2*$B$13^2)/200 -> 0.010078149 | H13: =E13*$B$17+(E13^2*$B$18^2)/200 -> 0.009374255 | I13: =$B$20-F13*$B$20 -> 109.25737 | J13: =$B$20-G13*$B$20 -> 108.8914 | K13: =$B$20-H13*$B$20 -> 108.96883
E14: 0.12 | F14: =E14*$B$7+(E14^2*$B$8^2)/200 -> 0.0073649114 | G14: =E14*$B$12+(E14^2*$B$13^2)/200 -> 0.010994347 | H14: =E14*$B$17+(E14^2*$B$18^2)/200 -> 0.010226469 | I14: =$B$20-F14*$B$20 -> 109.18986 | J14: =$B$20-G14*$B$20 -> 108.79062 | K14: =$B$20-H14*$B$20 -> 108.87509
A15: cosφ3 | B15: 0.8 | C15: ind | E15: 0.13 | F15: =E15*$B$7+(E15^2*$B$8^2)/200 -> 0.0079786867 | G15: =E15*$B$12+(E15^2*$B$13^2)/200 -> 0.011910545 | H15: =E15*$B$17+(E15^2*$B$18^2)/200 -> 0.011078685 | I15: =$B$20-F15*$B$20 -> 109.12234 | J15: =$B$20-G15*$B$20 -> 108.68984 | K15: =$B$20-H15*$B$20 -> 108.78134
A16: sinφ3 | B16: =(1-$B$15^2)^(1/2) -> 0.6 | C16: ind | E16: 0.14 | F16: =E16*$B$7+(E16^2*$B$8^2)/200 -> 0.008592467 | G16: =E16*$B$12+(E16^2*$B$13^2)/200 -> 0.012826743 | H16: =E16*$B$17+(E16^2*$B$18^2)/200 -> 0.011930902 | I16: =$B$20-F16*$B$20 -> 109.05483 | J16: =$B$20-G16*$B$20 -> 108.58906 | K16: =$B$20-H16*$B$20 -> 108.6876
A17: an%3 | B17: =$B$2*$B$15+$B$3*$B$16 -> 0.085219661 | E17: 0.15 | F17: =E17*$B$7+(E17^2*$B$8^2)/200 -> 0.0092062523 | G17: =E17*$B$12+(E17^2*$B$13^2)/200 -> 0.013742942 | H17: =E17*$B$17+(E17^2*$B$18^2)/200 -> 0.012783121 | I17: =$B$20-F17*$B$20 -> 108.98731 | J17: =$B$20-G17*$B$20 -> 108.48828 | K17: =$B$20-H17*$B$20 -> 108.59386
A18: bn%3 | B18: =$B$3*$B$15-$B$2*$B$16 -> -0.039072649 | E18: 0.16 | F18: =E18*$B$7+(E18^2*$B$8^2)/200 -> 0.0098200426 | G18: =E18*$B$12+(E18^2*$B$13^2)/200 -> 0.014659141 | H18: =E18*$B$17+(E18^2*$B$18^2)/200 -> 0.013635341 | I18: =$B$20-F18*$B$20 -> 108.9198 | J18: =$B$20-G18*$B$20 -> 108.38749 | K18: =$B$20-H18*$B$20 -> 108.50011
E19: 0.17 | F19: =E19*$B$7+(E19^2*$B$8^2)/200 -> 0.010433838 | G19: =E19*$B$12+(E19^2*$B$13^2)/200 -> 0.015575341 | H19: =E19*$B$17+(E19^2*$B$18^2)/200 -> 0.014487563 | I19: =$B$20-F19*$B$20 -> 108.85228 | J19: =$B$20-G19*$B$20 -> 108.28671 | K19: =$B$20-H19*$B$20 -> 108.40637
A20: U2n | B20: 110 | C20: V | E20: 0.18 | F20: =E20*$B$7+(E20^2*$B$8^2)/200 -> 0.011047638 | G20: =E20*$B$12+(E20^2*$B$13^2)/200 -> 0.016491541 | H20: =E20*$B$17+(E20^2*$B$18^2)/200 -> 0.015339786 | I20: =$B$20-F20*$B$20 -> 108.78476 | J20: =$B$20-G20*$B$20 -> 108.18593 | K20: =$B$20-H20*$B$20 -> 108.31262
E21: 0.19 | F21: =E21*$B$7+(E21^2*$B$8^2)/200 -> 0.011661444 | G21: =E21*$B$12+(E21^2*$B$13^2)/200 -> 0.017407742 | H21: =E21*$B$17+(E21^2*$B$18^2)/200 -> 0.016192011 | I21: =$B$20-F21*$B$20 -> 108.71724 | J21: =$B$20-G21*$B$20 -> 108.08515 | K21: =$B$20-H21*$B$20 -> 108.21888
E22: 0.2 | F22: =E22*$B$7+(E22^2*$B$8^2)/200 -> 0.012275254 | G22: =E22*$B$12+(E22^2*$B$13^2)/200 -> 0.018323943 | H22: =E22*$B$17+(E22^2*$B$18^2)/200 -> 0.017044237 | I22: =$B$20-F22*$B$20 -> 108.64972 | J22: =$B$20-G22*$B$20 -> 107.98437 | K22: =$B$20-H22*$B$20 -> 108.12513
E23: 0.21 | F23: =E23*$B$7+(E23^2*$B$8^2)/200 -> 0.01288907 | G23: =E23*$B$12+(E23^2*$B$13^2)/200 -> 0.019240144 | H23: =E23*$B$17+(E23^2*$B$18^2)/200 -> 0.017896465 | I23: =$B$20-F23*$B$20 -> 108.5822 | J23: =$B$20-G23*$B$20 -> 107.88358 | K23: =$B$20-H23*$B$20 -> 108.03139
E24: 0.22 | F24: =E24*$B$7+(E24^2*$B$8^2)/200 -> 0.01350289 | G24: =E24*$B$12+(E24^2*$B$13^2)/200 -> 0.020156346 | H24: =E24*$B$17+(E24^2*$B$18^2)/200 -> 0.018748695 | I24: =$B$20-F24*$B$20 -> 108.51468 | J24: =$B$20-G24*$B$20 -> 107.7828 | K24: =$B$20-H24*$B$20 -> 107.93764
E25: 0.23 | F25: =E25*$B$7+(E25^2*$B$8^2)/200 -> 0.014116716 | G25: =E25*$B$12+(E25^2*$B$13^2)/200 -> 0.021072548 | H25: =E25*$B$17+(E25^2*$B$18^2)/200 -> 0.019600926 | I25: =$B$20-F25*$B$20 -> 108.44716 | J25: =$B$20-G25*$B$20 -> 107.68202 | K25: =$B$20-H25*$B$20 -> 107.8439
E26: 0.24 | F26: =E26*$B$7+(E26^2*$B$8^2)/200 -> 0.014730546 | G26: =E26*$B$12+(E26^2*$B$13^2)/200 -> 0.02198875 | H26: =E26*$B$17+(E26^2*$B$18^2)/200 -> 0.020453158 | I26: =$B$20-F26*$B$20 -> 108.37964 | J26: =$B$20-G26*$B$20 -> 107.58124 | K26: =$B$20-H26*$B$20 -> 107.75015
E27: 0.25 | F27: =E27*$B$7+(E27^2*$B$8^2)/200 -> 0.015344382 | G27: =E27*$B$12+(E27^2*$B$13^2)/200 -> 0.022904953 | H27: =E27*$B$17+(E27^2*$B$18^2)/200 -> 0.021305392 | I27: =$B$20-F27*$B$20 -> 108.31212 | J27: =$B$20-G27*$B$20 -> 107.48046 | K27: =$B$20-H27*$B$20 -> 107.65641
E28: 0.26 | F28: =E28*$B$7+(E28^2*$B$8^2)/200 -> 0.015958222 | G28: =E28*$B$12+(E28^2*$B$13^2)/200 -> 0.023821156 | H28: =E28*$B$17+(E28^2*$B$18^2)/200 -> 0.022157628 | I28: =$B$20-F28*$B$20 -> 108.2446 | J28: =$B$20-G28*$B$20 -> 107.37967 | K28: =$B$20-H28*$B$20 -> 107.56266
E29: 0.27 | F29: =E29*$B$7+(E29^2*$B$8^2)/200 -> 0.016572068 | G29: =E29*$B$12+(E29^2*$B$13^2)/200 -> 0.02473736 | H29: =E29*$B$17+(E29^2*$B$18^2)/200 -> 0.023009865 | I29: =$B$20-F29*$B$20 -> 108.17707 | J29: =$B$20-G29*$B$20 -> 107.27889 | K29: =$B$20-H29*$B$20 -> 107.46891
E30: 0.28 | F30: =E30*$B$7+(E30^2*$B$8^2)/200 -> 0.017185918 | G30: =E30*$B$12+(E30^2*$B$13^2)/200 -> 0.025653564 | H30: =E30*$B$17+(E30^2*$B$18^2)/200 -> 0.023862103 | I30: =$B$20-F30*$B$20 -> 108.10955 | J30: =$B$20-G30*$B$20 -> 107.17811 | K30: =$B$20-H30*$B$20 -> 107.37517
E31: 0.29 | F31: =E31*$B$7+(E31^2*$B$8^2)/200 -> 0.017799774 | G31: =E31*$B$12+(E31^2*$B$13^2)/200 -> 0.026569768 | H31: =E31*$B$17+(E31^2*$B$18^2)/200 -> 0.024714344 | I31: =$B$20-F31*$B$20 -> 108.04202 | J31: =$B$20-G31*$B$20 -> 107.07733 | K31: =$B$20-H31*$B$20 -> 107.28142
E32: 0.3 | F32: =E32*$B$7+(E32^2*$B$8^2)/200 -> 0.018413635 | G32: =E32*$B$12+(E32^2*$B$13^2)/200 -> 0.027485973 | H32: =E32*$B$17+(E32^2*$B$18^2)/200 -> 0.025566585 | I32: =$B$20-F32*$B$20 -> 107.9745 | J32: =$B$20-G32*$B$20 -> 106.97654 | K32: =$B$20-H32*$B$20 -> 107.18768
... E102: 1 | F102: =E102*$B$7+(E102^2*$B$8^2)/200 -> 0.061396362 | G102: =E102*$B$12+(E102^2*$B$13^2)/200 -> 0.091621293 | H102: =E102*$B$17+(E102^2*$B$18^2)/200 -> 0.085227294 | I102: =$B$20-F102*$B$20 -> 103.2464 | J102: =$B$20-G102*$B$20 -> 99.921658 | K102: =$B$20-H102*$B$20 -> 100.625

Sheet Пораст температуре
A1: RBM | B1: t [min] | C1: Udc [V] | F1: Idc [mA] | I1: R'dc, T [Ω] | J1: T [°C]
C2: α | D2: k | F2: α | G2: k
A3: 1 | B3: 0 | C3: 11.6 | D3: 1 | E3: =C3*D3 -> 11.6 | F3: 210 | G3: 1 | H3: =F3*G3 -> 210 | I3: =E3/(H3/1000) -> 55.238095 | J3: =(I3/$B$16)*(235+$B$15)-235+4.82 -> 20.59899
A4: 2 | B4: 5 | C4: 11.5 | D4: 1 | E4: =C4*D4 -> 11.5 | F4: 190 | G4: 1 | H4: =F4*G4 -> 190 | I4: =E4/(H4/1000) -> 60.526316 | J4: =(I4/$B$16)*(235+$B$15)-235 -> 39.787324
A5: 3 | B5: 10 | C5: 11.7 | D5: 1 | E5: =C5*D5 -> 11.7 | F5: 185 | G5: 1 | H5: =F5*G5 -> 185 | I5: =E5/(H5/1000) -> 63.243243 | J5: =(I5/$B$16)*(235+$B$15)-235 -> 52.122078
A6: 4 | B6: 15 | C6: 11.85 | D6: 1 | E6: =C6*D6 -> 11.85 | F6: 180 | G6: 1 | H6: =F6*G6 -> 180 | I6: =E6/(H6/1000) -> 65.833333 | J6: =(I6/$B$16)*(235+$B$15)-235 -> 63.880995
A7: 5 | B7: 20 | C7: 11.9 | D7: 1 | E7: =C7*D7 -> 11.9 | F7: 180 | G7: 1 | H7: =F7*G7 -> 180 | I7: =E7/(H7/1000) -> 66.111111 | J7: =(I7/$B$16)*(235+$B$15)-235 -> 65.142096
A8: 6 | B8: 25 | C8: 11.95 | D8: 1 | E8: =C8*D8 -> 11.95 | F8: 185 | G8: 1 | H8: =F8*G8 -> 185 | I8: =E8/(H8/1000) -> 64.594595 | J8: =(I8/$B$16)*(235+$B$15)-235 -> 58.257165
A9: 7 | B9: 30 | C9: 11.95 | D9: 1 | E9: =C9*D9 -> 11.95 | F9: 185 | G9: 1 | H9: =F9*G9 -> 185 | I9: =E9/(H9/1000) -> 64.594595 | J9: =(I9/$B$16)*(235+$B$15)-235 -> 58.257165
A10: 8 | B10: 35 | C10: 11.85 | D10: 1 | E10: =C10*D10 -> 11.85 | F10: 185 | G10: 1 | H10: =F10*G10 -> 185 | I10: =E10/(H10/1000) -> 64.054054 | J10: =(I10/$B$16)*(235+$B$15)-235 -> 55.80313
A11: 9 | B11: 40 | C11: 11.8 | D11: 1 | E11: =C11*D11 -> 11.8 | F11: 175 | G11: 1 | H11: =F11*G11 -> 175 | I11: =E11/(H11/1000) -> 67.428571 | J11: =(I11/$B$16)*(235+$B$15)-235 -> 71.123319
A12: 10 | B12: 45 | C12: 11.8 | D12: 1 | E12: =C12*D12 -> 11.8 | F12: 170 | G12: 1 | H12: =F12*G12 -> 170 | I12: =E12/(H12/1000) -> 69.411765 | J12: =(I12/$B$16)*(235+$B$15)-235 -> 80.126946
A15: ϑa | B15: 20.6 | C15: °C
A16: R'dc | B16: 56.3 | C16: Ω
A17: ϑ | B17: 75 | C17: °C
A18: R'dc, T | B18: =#REF!*(235+$B$18)/(235+$B$16) -> 68.282473 | C18: Ω
